Workbook

Sheet X - MLP v4
B1: input V | I1: tocols HLS | J1: tocols SW | K1: Weight N1, hidden | L1: Weight N2, hidden | M1: w, output | O1: 7th bit | P1: N1 before rounding | Q1: N1 | R1: sigmoid N1 | T1: 7th bit | U1: N2 bf rounding | V1: N2 after rounding | W1: sigmoid N2 | Y1: 7th bit | Z1: Solution | AA1: Hex sol | AB1: Prediction | AC1: Actual | AF1: accuracy
A2: 255 | B2: 44 | C2: 90 | D2: 0 | E2: 0 | F2: 24 | G2: 81 | H2: 22 | I2: {=_xlfn.TOCOL(A2:H65)} -> 255 | J2: {=_xlfn.TOCOL(B2:H65)} -> 44 | K2: 26 | L2: 6 | M2: 80 | N2: {=MMULT(A2:H2,$K$2:$K$9)} -> 12007 | O2: =IF(_xlfn.BITAND(N2,128), 1, 0) -> 1 | P2: {=_xlfn.BITRSHIFT(MMULT(A2:H65, K2:K9),8)} -> 46 | Q2: =P2+O2 -> 47 | R2: {=INDEX(Sigmoid!$1:$1,Q2)} -> 32 | S2: {=MMULT(A2:H2,$L$2:$L$9)} -> 5253 | T2: =IF(_xlfn.BITAND(S2,128), 1, 0) -> 1 | U2: {=_xlfn.BITRSHIFT(MMULT(A2:H65, L2:L9),8)} -> 20 | V2: =U2+T2 -> 21 | W2: {=INDEX(Sigmoid!$1:$1, V2)} -> 18 | X2: =255*$M$2 +R2*$M$3 +W2*$M$4 -> 25600 | Y2: =IF(_xlfn.BITAND(X2,128), 1, 0) -> 0 | Z2: =_xlfn.BITRSHIFT(X2, 8) + Y2 -> 100 | AA2: =DEC2HEX(Z2,2) -> 64 | AB2: =IF(Z2 < 128, 0, 1) -> 0 | AC2: 0 | AD2: =AB2=AC2 -> TRUE | AE2: 1 | AF2: =100*COUNTIF(AD2:AD65, TRUE)/COUNTA(AD2:AD65) -> 98.4375 | AH2: 100 | AI2: 100
A3: 255 | B3: 159 | C3: 250 | D3: 140 | E3: 176 | F3: 121 | G3: 183 | H3: 138 | I3: 44 | J3: 90 | K3: 25 | L3: 18 | M3: 50 | N3: {=MMULT(A3:H3,$K$2:$K$9)} -> 32009 | O3: =IF(_xlfn.BITAND(N3,128), 1, 0) -> 0 | P3: 125 | Q3: =P3+O3 -> 125 | R3: {=INDEX(Sigmoid!$1:$1,Q3)} -> 122 | S3: {=MMULT(A3:H3,$L$2:$L$9)} -> 20953 | T3: =IF(_xlfn.BITAND(S3,128), 1, 0) -> 1 | U3: 81 | V3: =U3+T3 -> 82 | W3: {=INDEX(Sigmoid!$1:$1, V3)} -> 63 | X3: =255*$M$2 +R3*$M$3 +W3*$M$4 -> 39100 | Y3: =IF(_xlfn.BITAND(X3,128), 1, 0) -> 1 | Z3: =_xlfn.BITRSHIFT(X3, 8) + Y3 -> 153 | AA3: =DEC2HEX(Z3,2) -> 99 | AB3: =IF(Z3 < 128, 0, 1) -> 1 | AC3: 1 | AD3: =AB3=AC3 -> TRUE | AE3: 1 | AH3: 153 | AI3: 153
A4: 255 | B4: 167 | C4: 158 | D4: 172 | E4: 134 | F4: 172 | G4: 161 | H4: 118 | I4: 90 | J4: 0 | K4: 31 | L4: 6 | M4: 200 | N4: {=MMULT(A4:H4,$K$2:$K$9)} -> 28650 | O4: =IF(_xlfn.BITAND(N4,128), 1, 0) -> 1 | P4: 111 | Q4: =P4+O4 -> 112 | R4: {=INDEX(Sigmoid!$1:$1,Q4)} -> 102 | S4: {=MMULT(A4:H4,$L$2:$L$9)} -> 21665 | T4: =IF(_xlfn.BITAND(S4,128), 1, 0) -> 1 | U4: 84 | V4: =U4+T4 -> 85 | W4: {=INDEX(Sigmoid!$1:$1, V4)} -> 67 | X4: =255*$M$2 +R4*$M$3 +W4*$M$4 -> 38900 | Y4: =IF(_xlfn.BITAND(X4,128), 1, 0) -> 1 | Z4: =_xlfn.BITRSHIFT(X4, 8) + Y4 -> 152 | AA4: =DEC2HEX(Z4,2) -> 98 | AB4: =IF(Z4 < 128, 0, 1) -> 1 | AC4: 1 | AD4: =AB4=AC4 -> TRUE | AE4: 1 | AH4: 152 | AI4: 152
A5: 255 | B5: 130 | C5: 178 | D5: 136 | E5: 120 | F5: 135 | G5: 121 | H5: 86 | I5: 0 | J5: 0 | K5: 29 | L5: 26 | N5: {=MMULT(A5:H5,$K$2:$K$9)} -> 25684 | O5: =IF(_xlfn.BITAND(N5,128), 1, 0) -> 0 | P5: 100 | Q5: =P5+O5 -> 100 | R5: {=INDEX(Sigmoid!$1:$1,Q5)} -> 86 | S5: {=MMULT(A5:H5,$L$2:$L$9)} -> 17333 | T5: =IF(_xlfn.BITAND(S5,128), 1, 0) -> 1 | U5: 67 | V5: =U5+T5 -> 68 | W5: {=INDEX(Sigmoid!$1:$1, V5)} -> 49 | X5: =255*$M$2 +R5*$M$3 +W5*$M$4 -> 34500 | Y5: =IF(_xlfn.BITAND(X5,128), 1, 0) -> 1 | Z5: =_xlfn.BITRSHIFT(X5, 8) + Y5 -> 135 | AA5: =DEC2HEX(Z5,2) -> 87 | AB5: =IF(Z5 < 128, 0, 1) -> 1 | AC5: 1 | AD5: =AB5=AC5 -> TRUE | AE5: 0 | AH5: 135 | AI5: 135
A6: 255 | B6: 34 | C6: 112 | D6: 142 | E6: 112 | F6: 163 | G6: 159 | H6: 43 | I6: 0 | J6: 24 | K6: 22 | L6: 1 | N6: {=MMULT(A6:H6,$K$2:$K$9)} -> 20564 | O6: =IF(_xlfn.BITAND(N6,128), 1, 0) -> 0 | P6: 80 | Q6: =P6+O6 -> 80 | R6: {=INDEX(Sigmoid!$1:$1,Q6)} -> 61 | S6: {=MMULT(A6:H6,$L$2:$L$9)} -> 14548 | T6: =IF(_xlfn.BITAND(S6,128), 1, 0) -> 1 | U6: 56 | V6: =U6+T6 -> 57 | W6: {=INDEX(Sigmoid!$1:$1, V6)} -> 39 | X6: =255*$M$2 +R6*$M$3 +W6*$M$4 -> 31250 | Y6: =IF(_xlfn.BITAND(X6,128), 1, 0) -> 0 | Z6: =_xlfn.BITRSHIFT(X6, 8) + Y6 -> 122 | AA6: =DEC2HEX(Z6,2) -> 7A | AB6: =IF(Z6 < 128, 0, 1) -> 0 | AC6: 0 | AD6: =AB6=AC6 -> TRUE | AE6: 1 | AH6: 122 | AI6: 122
A7: 255 | B7: 63 | C7: 28 | D7: 145 | E7: 126 | F7: 190 | G7: 165 | H7: 66 | I7: 24 | J7: 81 | K7: 1 | L7: 28 | N7: {=MMULT(A7:H7,$K$2:$K$9)} -> 19771 | O7: =IF(_xlfn.BITAND(N7,128), 1, 0) -> 0 | P7: 77 | Q7: =P7+O7 -> 77 | R7: {=INDEX(Sigmoid!$1:$1,Q7)} -> 58 | S7: {=MMULT(A7:H7,$L$2:$L$9)} -> 16503 | T7: =IF(_xlfn.BITAND(S7,128), 1, 0) -> 0 | U7: 64 | V7: =U7+T7 -> 64 | W7: {=INDEX(Sigmoid!$1:$1, V7)} -> 45 | X7: =255*$M$2 +R7*$M$3 +W7*$M$4 -> 32300 | Y7: =IF(_xlfn.BITAND(X7,128), 1, 0) -> 0 | Z7: =_xlfn.BITRSHIFT(X7, 8) + Y7 -> 126 | AA7: =DEC2HEX(Z7,2) -> 7E | AB7: =IF(Z7 < 128, 0, 1) -> 0 | AC7: 0 | AD7: =AB7=AC7 -> TRUE | AE7: 1 | AH7: 126 | AI7: 126
A8: 255 | B8: 88 | C8: 214 | D8: 157 | E8: 140 | F8: 205 | G8: 174 | H8: 128 | I8: 81 | J8: 22 | K8: 11 | L8: 9 | N8: {=MMULT(A8:H8,$K$2:$K$9)} -> 28544 | O8: =IF(_xlfn.BITAND(N8,128), 1, 0) -> 1 | P8: 111 | Q8: =P8+O8 -> 112 | R8: {=INDEX(Sigmoid!$1:$1,Q8)} -> 102 | S8: {=MMULT(A8:H8,$L$2:$L$9)} -> 21686 | T8: =IF(_xlfn.BITAND(S8,128), 1, 0) -> 1 | U8: 84 | V8: =U8+T8 -> 85 | W8: {=INDEX(Sigmoid!$1:$1, V8)} -> 67 | X8: =255*$M$2 +R8*$M$3 +W8*$M$4 -> 38900 | Y8: =IF(_xlfn.BITAND(X8,128), 1, 0) -> 1 | Z8: =_xlfn.BITRSHIFT(X8, 8) + Y8 -> 152 | AA8: =DEC2HEX(Z8,2) -> 98 | AB8: =IF(Z8 < 128, 0, 1) -> 1 | AC8: 1 | AD8: =AB8=AC8 -> TRUE | AE8: 1 | AH8: 152 | AI8: 152
A9: 255 | B9: 185 | C9: 203 | D9: 170 | E9: 110 | F9: 211 | G9: 138 | H9: 126 | I9: 22 | J9: 159 | K9: 26 | L9: 45 | N9: {=MMULT(A9:H9,$K$2:$K$9)} -> 29903 | O9: =IF(_xlfn.BITAND(N9,128), 1, 0) -> 1 | P9: 116 | Q9: =P9+O9 -> 117 | R9: {=INDEX(Sigmoid!$1:$1,Q9)} -> 110 | S9: {=MMULT(A9:H9,$L$2:$L$9)} -> 23428 | T9: =IF(_xlfn.BITAND(S9,128), 1, 0) -> 1 | U9: 91 | V9: =U9+T9 -> 92 | W9: {=INDEX(Sigmoid!$1:$1, V9)} -> 75 | X9: =255*$M$2 +R9*$M$3 +W9*$M$4 -> 40900 | Y9: =IF(_xlfn.BITAND(X9,128), 1, 0) -> 1 | Z9: =_xlfn.BITRSHIFT(X9, 8) + Y9 -> 160 | AA9: =DEC2HEX(Z9,2) -> A0 | AB9: =IF(Z9 < 128, 0, 1) -> 1 | AC9: 1 | AD9: =AB9=AC9 -> TRUE | AE9: 1 | AH9: 160 | AI9: 160
A10: 255 | B10: 140 | C10: 255 | D10: 110 | E10: 136 | F10: 133 | G10: 156 | H10: 131 | I10: 255 | J10: 250 | N10: {=MMULT(A10:H10,$K$2:$K$9)} -> 29472 | O10: =IF(_xlfn.BITAND(N10,128), 1, 0) -> 0 | P10: 115 | Q10: =P10+O10 -> 115 | R10: {=INDEX(Sigmoid!$1:$1,Q10)} -> 107 | S10: {=MMULT(A10:H10,$L$2:$L$9)} -> 19599 | T10: =IF(_xlfn.BITAND(S10,128), 1, 0) -> 1 | U10: 76 | V10: =U10+T10 -> 77 | W10: {=INDEX(Sigmoid!$1:$1, V10)} -> 58 | X10: =255*$M$2 +R10*$M$3 +W10*$M$4 -> 37350 | Y10: =IF(_xlfn.BITAND(X10,128), 1, 0) -> 1 | Z10: =_xlfn.BITRSHIFT(X10, 8) + Y10 -> 146 | AA10: =DEC2HEX(Z10,2) -> 92 | AB10: =IF(Z10 < 128, 0, 1) -> 1 | AC10: 1 | AD10: =AB10=AC10 -> TRUE | AE10: 1 | AH10: 146 | AI10: 146
A11: 255 | B11: 73 | C11: 90 | D11: 164 | E11: 118 | F11: 75 | G11: 121 | H11: 111 | I11: 159 | J11: 140 | N11: {=MMULT(A11:H11,$K$2:$K$9)} -> 22889 | O11: =IF(_xlfn.BITAND(N11,128), 1, 0) -> 0 | P11: 89 | Q11: =P11+O11 -> 89 | R11: {=INDEX(Sigmoid!$1:$1,Q11)} -> 72 | S11: {=MMULT(A11:H11,$L$2:$L$9)} -> 15950 | T11: =IF(_xlfn.BITAND(S11,128), 1, 0) -> 0 | U11: 62 | V11: =U11+T11 -> 62 | W11: {=INDEX(Sigmoid!$1:$1, V11)} -> 44 | X11: =255*$M$2 +R11*$M$3 +W11*$M$4 -> 32800 | Y11: =IF(_xlfn.BITAND(X11,128), 1, 0) -> 0 | Z11: =_xlfn.BITRSHIFT(X11, 8) + Y11 -> 128 | AA11: =DEC2HEX(Z11,2) -> 80 | AB11: =IF(Z11 < 128, 0, 1) -> 1 | AC11: 0 | AD11: =AB11=AC11 -> FALSE | AE11: 1 | AH11: 128 | AI11: 128
A12: 255 | B12: 16 | C12: 93 | D12: 187 | E12: 88 | F12: 162 | G12: 101 | H12: 27 | I12: 250 | J12: 176 | N12: {=MMULT(A12:H12,$K$2:$K$9)} -> 19247 | O12: =IF(_xlfn.BITAND(N12,128), 1, 0) -> 0 | P12: 75 | Q12: =P12+O12 -> 75 | R12: {=INDEX(Sigmoid!$1:$1,Q12)} -> 56 | S12: {=MMULT(A12:H12,$L$2:$L$9)} -> 13986 | T12: =IF(_xlfn.BITAND(S12,128), 1, 0) -> 1 | U12: 54 | V12: =U12+T12 -> 55 | W12: {=INDEX(Sigmoid!$1:$1, V12)} -> 38 | X12: =255*$M$2 +R12*$M$3 +W12*$M$4 -> 30800 | Y12: =IF(_xlfn.BITAND(X12,128), 1, 0) -> 0 | Z12: =_xlfn.BITRSHIFT(X12, 8) + Y12 -> 120 | AA12: =DEC2HEX(Z12,2) -> 78 | AB12: =IF(Z12 < 128, 0, 1) -> 0 | AC12: 0 | AD12: =AB12=AC12 -> TRUE | AE12: 1 | AH12: 121 | AI12: 120
A13: 255 | B13: 31 | C13: 110 | D13: 120 | E13: 77 | F13: 166 | G13: 101 | H13: 45 | I13: 140 | J13: 121 | N13: {=MMULT(A13:H13,$K$2:$K$9)} -> 18436 | O13: =IF(_xlfn.BITAND(N13,128), 1, 0) -> 0 | P13: 72 | Q13: =P13+O13 -> 72 | R13: {=INDEX(Sigmoid!$1:$1,Q13)} -> 53 | S13: {=MMULT(A13:H13,$L$2:$L$9)} -> 13527 | T13: =IF(_xlfn.BITAND(S13,128), 1, 0) -> 1 | U13: 52 | V13: =U13+T13 -> 53 | W13: {=INDEX(Sigmoid!$1:$1, V13)} -> 36 | X13: =255*$M$2 +R13*$M$3 +W13*$M$4 -> 30250 | Y13: =IF(_xlfn.BITAND(X13,128), 1, 0) -> 0 | Z13: =_xlfn.BITRSHIFT(X13, 8) + Y13 -> 118 | AA13: =DEC2HEX(Z13,2) -> 76 | AB13: =IF(Z13 < 128, 0, 1) -> 0 | AC13: 0 | AD13: =AB13=AC13 -> TRUE | AE13: 1 | AH13: 118 | AI13: 118
A14: 255 | B14: 183 | C14: 181 | D14: 155 | E14: 175 | F14: 135 | G14: 211 | H14: 185 | I14: 176 | J14: 183 | N14: {=MMULT(A14:H14,$K$2:$K$9)} -> 32427 | O14: =IF(_xlfn.BITAND(N14,128), 1, 0) -> 1 | P14: 126 | Q14: =P14+O14 -> 127 | R14: {=INDEX(Sigmoid!$1:$1,Q14)} -> 125 | S14: {=MMULT(A14:H14,$L$2:$L$9)} -> 24119 | T14: =IF(_xlfn.BITAND(S14,128), 1, 0) -> 0 | U14: 94 | V14: =U14+T14 -> 94 | W14: {=INDEX(Sigmoid!$1:$1, V14)} -> 78 | X14: =255*$M$2 +R14*$M$3 +W14*$M$4 -> 42250 | Y14: =IF(_xlfn.BITAND(X14,128), 1, 0) -> 0 | Z14: =_xlfn.BITRSHIFT(X14, 8) + Y14 -> 165 | AA14: =DEC2HEX(Z14,2) -> A5 | AB14: =IF(Z14 < 128, 0, 1) -> 1 | AC14: 1 | AD14: =AB14=AC14 -> TRUE | AE14: 1 | AH14: 165 | AI14: 165
A15: 255 | B15: 129 | C15: 193 | D15: 104 | E15: 159 | F15: 184 | G15: 183 | H15: 161 | I15: 121 | J15: 138 | N15: {=MMULT(A15:H15,$K$2:$K$9)} -> 28735 | O15: =IF(_xlfn.BITAND(N15,128), 1, 0) -> 0 | P15: 112 | Q15: =P15+O15 -> 112 | R15: {=INDEX(Sigmoid!$1:$1,Q15)} -> 102 | S15: {=MMULT(A15:H15,$L$2:$L$9)} -> 21917 | T15: =IF(_xlfn.BITAND(S15,128), 1, 0) -> 1 | U15: 85 | V15: =U15+T15 -> 86 | W15: {=INDEX(Sigmoid!$1:$1, V15)} -> 68 | X15: =255*$M$2 +R15*$M$3 +W15*$M$4 -> 39100 | Y15: =IF(_xlfn.BITAND(X15,128), 1, 0) -> 1 | Z15: =_xlfn.BITRSHIFT(X15, 8) + Y15 -> 153 | AA15: =DEC2HEX(Z15,2) -> 99 | AB15: =IF(Z15 < 128, 0, 1) -> 1 | AC15: 1 | AD15: =AB15=AC15 -> TRUE | AE15: 1 | AH15: 153 | AI15: 153
A16: 255 | B16: 190 | C16: 183 | D16: 143 | E16: 124 | F16: 139 | G16: 138 | H16: 145 | I16: 183 | J16: 167 | N16: {=MMULT(A16:H16,$K$2:$K$9)} -> 29355 | O16: =IF(_xlfn.BITAND(N16,128), 1, 0) -> 1 | P16: 114 | Q16: =P16+O16 -> 115 | R16: {=INDEX(Sigmoid!$1:$1,Q16)} -> 107 | S16: {=MMULT(A16:H16,$L$2:$L$9)} -> 21549 | T16: =IF(_xlfn.BITAND(S16,128), 1, 0) -> 0 | U16: 84 | V16: =U16+T16 -> 84 | W16: {=INDEX(Sigmoid!$1:$1, V16)} -> 66 | X16: =255*$M$2 +R16*$M$3 +W16*$M$4 -> 38950 | Y16: =IF(_xlfn.BITAND(X16,128), 1, 0) -> 0 | Z16: =_xlfn.BITRSHIFT(X16, 8) + Y16 -> 152 | AA16: =DEC2HEX(Z16,2) -> 98 | AB16: =IF(Z16 < 128, 0, 1) -> 1 | AC16: 1 | AD16: =AB16=AC16 -> TRUE | AE16: 1 | AH16: 152 | AI16: 152
A17: 255 | B17: 79 | C17: 113 | D17: 115 | E17: 111 | F17: 164 | G17: 101 | H17: 88 | I17: 138 | J17: 158 | N17: {=MMULT(A17:H17,$K$2:$K$9)} -> 21448 | O17: =IF(_xlfn.BITAND(N17,128), 1, 0) -> 1 | P17: 83 | Q17: =P17+O17 -> 84 | R17: {=INDEX(Sigmoid!$1:$1,Q17)} -> 66 | S17: {=MMULT(A17:H17,$L$2:$L$9)} -> 16192 | T17: =IF(_xlfn.BITAND(S17,128), 1, 0) -> 0 | U17: 63 | V17: =U17+T17 -> 63 | W17: {=INDEX(Sigmoid!$1:$1, V17)} -> 44 | X17: =255*$M$2 +R17*$M$3 +W17*$M$4 -> 32500 | Y17: =IF(_xlfn.BITAND(X17,128), 1, 0) -> 1 | Z17: =_xlfn.BITRSHIFT(X17, 8) + Y17 -> 127 | AA17: =DEC2HEX(Z17,2) -> 7F | AB17: =IF(Z17 < 128, 0, 1) -> 0 | AC17: 0 | AD17: =AB17=AC17 -> TRUE | AE17: 1 | AH17: 127 | AI17: 127
A18: 255 | B18: 213 | C18: 213 | D18: 149 | E18: 159 | F18: 133 | G18: 199 | H18: 183 | I18: 255 | J18: 172 | N18: {=MMULT(A18:H18,$K$2:$K$9)} -> 33457 | O18: =IF(_xlfn.BITAND(N18,128), 1, 0) -> 1 | P18: 130 | Q18: =P18+O18 -> 131 | R18: {=INDEX(Sigmoid!$1:$1,Q18)} -> 130 | S18: {=MMULT(A18:H18,$L$2:$L$9)} -> 24425 | T18: =IF(_xlfn.BITAND(S18,128), 1, 0) -> 0 | U18: 95 | V18: =U18+T18 -> 95 | W18: {=INDEX(Sigmoid!$1:$1, V18)} -> 79 | X18: =255*$M$2 +R18*$M$3 +W18*$M$4 -> 42700 | Y18: =IF(_xlfn.BITAND(X18,128), 1, 0) -> 1 | Z18: =_xlfn.BITRSHIFT(X18, 8) + Y18 -> 167 | AA18: =DEC2HEX(Z18,2) -> A7 | AB18: =IF(Z18 < 128, 0, 1) -> 1 | AC18: 1 | AD18: =AB18=AC18 -> TRUE | AE18: 1 | AH18: 167 | AI18: 167
A19: 255 | B19: 13 | C19: 94 | D19: 127 | E19: 146 | F19: 132 | G19: 150 | H19: 89 | I19: 167 | J19: 134 | N19: {=MMULT(A19:H19,$K$2:$K$9)} -> 20860 | O19: =IF(_xlfn.BITAND(N19,128), 1, 0) -> 0 | P19: 81 | Q19: =P19+O19 -> 81 | R19: {=INDEX(Sigmoid!$1:$1,Q19)} -> 62 | S19: {=MMULT(A19:H19,$L$2:$L$9)} -> 14827 | T19: =IF(_xlfn.BITAND(S19,128), 1, 0) -> 1 | U19: 57 | V19: =U19+T19 -> 58 | W19: {=INDEX(Sigmoid!$1:$1, V19)} -> 40 | X19: =255*$M$2 +R19*$M$3 +W19*$M$4 -> 31500 | Y19: =IF(_xlfn.BITAND(X19,128), 1, 0) -> 0 | Z19: =_xlfn.BITRSHIFT(X19, 8) + Y19 -> 123 | AA19: =DEC2HEX(Z19,2) -> 7B | AB19: =IF(Z19 < 128, 0, 1) -> 0 | AC19: 0 | AD19: =AB19=AC19 -> TRUE | AE19: 1 | AH19: 123 | AI19: 123
A20: 255 | B20: 103 | C20: 175 | D20: 164 | E20: 139 | F20: 187 | G20: 147 | H20: 128 | I20: 158 | J20: 172 | N20: {=MMULT(A20:H20,$K$2:$K$9)} -> 27576 | O20: =IF(_xlfn.BITAND(N20,128), 1, 0) -> 1 | P20: 107 | Q20: =P20+O20 -> 108 | R20: {=INDEX(Sigmoid!$1:$1,Q20)} -> 97 | S20: {=MMULT(A20:H20,$L$2:$L$9)} -> 21156 | T20: =IF(_xlfn.BITAND(S20,128), 1, 0) -> 1 | U20: 82 | V20: =U20+T20 -> 83 | W20: {=INDEX(Sigmoid!$1:$1, V20)} -> 64 | X20: =255*$M$2 +R20*$M$3 +W20*$M$4 -> 38050 | Y20: =IF(_xlfn.BITAND(X20,128), 1, 0) -> 1 | Z20: =_xlfn.BITRSHIFT(X20, 8) + Y20 -> 149 | AA20: =DEC2HEX(Z20,2) -> 95 | AB20: =IF(Z20 < 128, 0, 1) -> 1 | AC20: 1 | AD20: =AB20=AC20 -> TRUE | AE20: 1 | AH20: 149 | AI20: 149
A21: 255 | B21: 42 | C21: 82 | D21: 104 | E21: 83 | F21: 167 | G21: 50 | H21: 71 | I21: 172 | J21: 161 | N21: {=MMULT(A21:H21,$K$2:$K$9)} -> 17627 | O21: =IF(_xlfn.BITAND(N21,128), 1, 0) -> 1 | P21: 68 | Q21: =P21+O21 -> 69 | R21: {=INDEX(Sigmoid!$1:$1,Q21)} -> 50 | S21: {=MMULT(A21:H21,$L$2:$L$9)} -> 13886 | T21: =IF(_xlfn.BITAND(S21,128), 1, 0) -> 0 | U21: 54 | V21: =U21+T21 -> 54 | W21: {=INDEX(Sigmoid!$1:$1, V21)} -> 37 | X21: =255*$M$2 +R21*$M$3 +W21*$M$4 -> 30300 | Y21: =IF(_xlfn.BITAND(X21,128), 1, 0) -> 0 | Z21: =_xlfn.BITRSHIFT(X21, 8) + Y21 -> 118 | AA21: =DEC2HEX(Z21,2) -> 76 | AB21: =IF(Z21 < 128, 0, 1) -> 0 | AC21: 0 | AD21: =AB21=AC21 -> TRUE | AE21: 1 | AH21: 119 | AI21: 118
... A65: 255 | B65: 19 | C65: 56 | D65: 140 | E65: 139 | F65: 217 | G65: 161 | H65: 51 | I65: 126 | J65: 73 | N65: {=MMULT(A65:H65,$K$2:$K$9)} -> 19273 | O65: =IF(_xlfn.BITAND(N65,128), 1, 0) -> 0 | P65: 75 | Q65: =P65+O65 -> 75 | R65: {=INDEX(Sigmoid!$1:$1,Q65)} -> 56 | S65: {=MMULT(A65:H65,$L$2:$L$9)} -> 15807 | T65: =IF(_xlfn.BITAND(S65,128), 1, 0) -> 1 | U65: 61 | V65: =U65+T65 -> 62 | W65: {=INDEX(Sigmoid!$1:$1, V65)} -> 44 | X65: =255*$M$2 +R65*$M$3 +W65*$M$4 -> 32000 | Y65: =IF(_xlfn.BITAND(X65,128), 1, 0) -> 0 | Z65: =_xlfn.BITRSHIFT(X65, 8) + Y65 -> 125 | AA65: =DEC2HEX(Z65,2) -> 7D | AB65: =IF(Z65 < 128, 0, 1) -> 0 | AC65: 0 | AD65: =AB65=AC65 -> TRUE | AE65: 1 | AH65: 125 | AI65: 125
I66: 255 | J66: 90
I67: 140 | J67: 164
I68: 255 | J68: 118
I69: 110 | J69: 75
I70: 136 | J70: 121
I71: 133 | J71: 111
I72: 156 | J72: 16
I73: 131 | J73: 93
I74: 255 | J74: 187
I75: 73 | J75: 88
I76: 90 | J76: 162
I77: 164 | J77: 101
... I449: 56 | J449: 51
I450: 255
I451: 37
I452: 70
I453: 131
I454: 53
...

Sheet X - MLP v3
B1: input V | I1: tocols HLS | J1: tocols SW | K1: Weight N1, hidden | L1: Weight N2, hidden | M1: w, output | O1: 7th bit | P1: N1 before rounding | Q1: N1 | R1: sigmoid N1 | T1: 7th bit | U1: N2 bf rounding | V1: N2 after rounding | W1: sigmoid N2 | Y1: 7th bit | Z1: Solution | AA1: Hex sol | AB1: Prediction | AC1: Actual | AF1: accuracy
A2: 255 | B2: 44 | C2: 90 | D2: 0 | E2: 0 | F2: 24 | G2: 81 | H2: 22 | I2: {=_xlfn.TOCOL(A2:H65)} -> 255 | J2: {=_xlfn.TOCOL(B2:H65)} -> 44 | K2: 26 | L2: 6 | M2: 80 | N2: {=MMULT(A2:H2,$K$2:$K$9)} -> 12007 | O2: =IF(_xlfn.BITAND(N2,128), 1, 0) -> 1 | P2: {=_xlfn.BITRSHIFT(MMULT(A2:H65, K2:K9),8)} -> 46 | Q2: =P2+O2 -> 47 | R2: {=INDEX(Sigmoid!$1:$1,Q2)} -> 32 | S2: {=MMULT(A2:H2,$L$2:$L$9)} -> 5253 | T2: =IF(_xlfn.BITAND(S2,128), 1, 0) -> 1 | U2: {=_xlfn.BITRSHIFT(MMULT(A2:H65, L2:L9),8)} -> 20 | V2: =U2+T2 -> 21 | W2: {=INDEX(Sigmoid!$1:$1, V2)} -> 18 | X2: =255*$M$2 +R2*$M$3 +W2*$M$4 -> 25600 | Y2: =IF(_xlfn.BITAND(X2,128), 1, 0) -> 0 | Z2: =_xlfn.BITRSHIFT(X2, 8) + Y2 -> 100 | AA2: =DEC2HEX(Z2,2) -> 64 | AB2: =IF(Z2 < 128, 0, 1) -> 0 | AC2: 0 | AD2: =AB2=AC2 -> TRUE | AE2: 1 | AF2: =100*COUNTIF(AD2:AD65, TRUE)/COUNTA(AD2:AD65) -> 98.4375 | AH2: 100 | AI2: 100
A3: 255 | B3: 159 | C3: 250 | D3: 140 | E3: 176 | F3: 121 | G3: 183 | H3: 138 | I3: 44 | J3: 90 | K3: 25 | L3: 18 | M3: 50 | N3: {=MMULT(A3:H3,$K$2:$K$9)} -> 32009 | O3: =IF(_xlfn.BITAND(N3,128), 1, 0) -> 0 | P3: 125 | Q3: =P3+O3 -> 125 | R3: {=INDEX(Sigmoid!$1:$1,Q3)} -> 122 | S3: {=MMULT(A3:H3,$L$2:$L$9)} -> 20953 | T3: =IF(_xlfn.BITAND(S3,128), 1, 0) -> 1 | U3: 81 | V3: =U3+T3 -> 82 | W3: {=INDEX(Sigmoid!$1:$1, V3)} -> 63 | X3: =255*$M$2 +R3*$M$3 +W3*$M$4 -> 39100 | Y3: =IF(_xlfn.BITAND(X3,128), 1, 0) -> 1 | Z3: =_xlfn.BITRSHIFT(X3, 8) + Y3 -> 153 | AA3: =DEC2HEX(Z3,2) -> 99 | AB3: =IF(Z3 < 128, 0, 1) -> 1 | AC3: 1 | AD3: =AB3=AC3 -> TRUE | AE3: 1 | AH3: 153 | AI3: 153
A4: 255 | B4: 167 | C4: 158 | D4: 172 | E4: 134 | F4: 172 | G4: 161 | H4: 118 | I4: 90 | J4: 0 | K4: 31 | L4: 6 | M4: 200 | N4: {=MMULT(A4:H4,$K$2:$K$9)} -> 28650 | O4: =IF(_xlfn.BITAND(N4,128), 1, 0) -> 1 | P4: 111 | Q4: =P4+O4 -> 112 | R4: {=INDEX(Sigmoid!$1:$1,Q4)} -> 102 | S4: {=MMULT(A4:H4,$L$2:$L$9)} -> 21665 | T4: =IF(_xlfn.BITAND(S4,128), 1, 0) -> 1 | U4: 84 | V4: =U4+T4 -> 85 | W4: {=INDEX(Sigmoid!$1:$1, V4)} -> 67 | X4: =255*$M$2 +R4*$M$3 +W4*$M$4 -> 38900 | Y4: =IF(_xlfn.BITAND(X4,128), 1, 0) -> 1 | Z4: =_xlfn.BITRSHIFT(X4, 8) + Y4 -> 152 | AA4: =DEC2HEX(Z4,2) -> 98 | AB4: =IF(Z4 < 128, 0, 1) -> 1 | AC4: 1 | AD4: =AB4=AC4 -> TRUE | AE4: 1 | AH4: 152 | AI4: 152
A5: 255 | B5: 130 | C5: 178 | D5: 136 | E5: 120 | F5: 135 | G5: 121 | H5: 86 | I5: 0 | J5: 0 | K5: 29 | L5: 26 | N5: {=MMULT(A5:H5,$K$2:$K$9)} -> 25684 | O5: =IF(_xlfn.BITAND(N5,128), 1, 0) -> 0 | P5: 100 | Q5: =P5+O5 -> 100 | R5: {=INDEX(Sigmoid!$1:$1,Q5)} -> 86 | S5: {=MMULT(A5:H5,$L$2:$L$9)} -> 17333 | T5: =IF(_xlfn.BITAND(S5,128), 1, 0) -> 1 | U5: 67 | V5: =U5+T5 -> 68 | W5: {=INDEX(Sigmoid!$1:$1, V5)} -> 49 | X5: =255*$M$2 +R5*$M$3 +W5*$M$4 -> 34500 | Y5: =IF(_xlfn.BITAND(X5,128), 1, 0) -> 1 | Z5: =_xlfn.BITRSHIFT(X5, 8) + Y5 -> 135 | AA5: =DEC2HEX(Z5,2) -> 87 | AB5: =IF(Z5 < 128, 0, 1) -> 1 | AC5: 1 | AD5: =AB5=AC5 -> TRUE | AE5: 0 | AH5: 135 | AI5: 135
A6: 255 | B6: 34 | C6: 112 | D6: 142 | E6: 112 | F6: 163 | G6: 159 | H6: 43 | I6: 0 | J6: 24 | K6: 22 | L6: 1 | N6: {=MMULT(A6:H6,$K$2:$K$9)} -> 20564 | O6: =IF(_xlfn.BITAND(N6,128), 1, 0) -> 0 | P6: 80 | Q6: =P6+O6 -> 80 | R6: {=INDEX(Sigmoid!$1:$1,Q6)} -> 61 | S6: {=MMULT(A6:H6,$L$2:$L$9)} -> 14548 | T6: =IF(_xlfn.BITAND(S6,128), 1, 0) -> 1 | U6: 56 | V6: =U6+T6 -> 57 | W6: {=INDEX(Sigmoid!$1:$1, V6)} -> 39 | X6: =255*$M$2 +R6*$M$3 +W6*$M$4 -> 31250 | Y6: =IF(_xlfn.BITAND(X6,128), 1, 0) -> 0 | Z6: =_xlfn.BITRSHIFT(X6, 8) + Y6 -> 122 | AA6: =DEC2HEX(Z6,2) -> 7A | AB6: =IF(Z6 < 128, 0, 1) -> 0 | AC6: 0 | AD6: =AB6=AC6 -> TRUE | AE6: 1 | AH6: 122 | AI6: 122
A7: 255 | B7: 63 | C7: 28 | D7: 145 | E7: 126 | F7: 190 | G7: 165 | H7: 66 | I7: 24 | J7: 81 | K7: 1 | L7: 28 | N7: {=MMULT(A7:H7,$K$2:$K$9)} -> 19771 | O7: =IF(_xlfn.BITAND(N7,128), 1, 0) -> 0 | P7: 77 | Q7: =P7+O7 -> 77 | R7: {=INDEX(Sigmoid!$1:$1,Q7)} -> 58 | S7: {=MMULT(A7:H7,$L$2:$L$9)} -> 16503 | T7: =IF(_xlfn.BITAND(S7,128), 1, 0) -> 0 | U7: 64 | V7: =U7+T7 -> 64 | W7: {=INDEX(Sigmoid!$1:$1, V7)} -> 45 | X7: =255*$M$2 +R7*$M$3 +W7*$M$4 -> 32300 | Y7: =IF(_xlfn.BITAND(X7,128), 1, 0) -> 0 | Z7: =_xlfn.BITRSHIFT(X7, 8) + Y7 -> 126 | AA7: =DEC2HEX(Z7,2) -> 7E | AB7: =IF(Z7 < 128, 0, 1) -> 0 | AC7: 0 | AD7: =AB7=AC7 -> TRUE | AE7: 1 | AH7: 126 | AI7: 126
A8: 255 | B8: 88 | C8: 214 | D8: 157 | E8: 140 | F8: 205 | G8: 174 | H8: 128 | I8: 81 | J8: 22 | K8: 11 | L8: 9 | N8: {=MMULT(A8:H8,$K$2:$K$9)} -> 28544 | O8: =IF(_xlfn.BITAND(N8,128), 1, 0) -> 1 | P8: 111 | Q8: =P8+O8 -> 112 | R8: {=INDEX(Sigmoid!$1:$1,Q8)} -> 102 | S8: {=MMULT(A8:H8,$L$2:$L$9)} -> 21686 | T8: =IF(_xlfn.BITAND(S8,128), 1, 0) -> 1 | U8: 84 | V8: =U8+T8 -> 85 | W8: {=INDEX(Sigmoid!$1:$1, V8)} -> 67 | X8: =255*$M$2 +R8*$M$3 +W8*$M$4 -> 38900 | Y8: =IF(_xlfn.BITAND(X8,128), 1, 0) -> 1 | Z8: =_xlfn.BITRSHIFT(X8, 8) + Y8 -> 152 | AA8: =DEC2HEX(Z8,2) -> 98 | AB8: =IF(Z8 < 128, 0, 1) -> 1 | AC8: 1 | AD8: =AB8=AC8 -> TRUE | AE8: 1 | AH8: 152 | AI8: 152
A9: 255 | B9: 185 | C9: 203 | D9: 170 | E9: 110 | F9: 211 | G9: 138 | H9: 126 | I9: 22 | J9: 159 | K9: 26 | L9: 45 | N9: {=MMULT(A9:H9,$K$2:$K$9)} -> 29903 | O9: =IF(_xlfn.BITAND(N9,128), 1, 0) -> 1 | P9: 116 | Q9: =P9+O9 -> 117 | R9: {=INDEX(Sigmoid!$1:$1,Q9)} -> 110 | S9: {=MMULT(A9:H9,$L$2:$L$9)} -> 23428 | T9: =IF(_xlfn.BITAND(S9,128), 1, 0) -> 1 | U9: 91 | V9: =U9+T9 -> 92 | W9: {=INDEX(Sigmoid!$1:$1, V9)} -> 75 | X9: =255*$M$2 +R9*$M$3 +W9*$M$4 -> 40900 | Y9: =IF(_xlfn.BITAND(X9,128), 1, 0) -> 1 | Z9: =_xlfn.BITRSHIFT(X9, 8) + Y9 -> 160 | AA9: =DEC2HEX(Z9,2) -> A0 | AB9: =IF(Z9 < 128, 0, 1) -> 1 | AC9: 1 | AD9: =AB9=AC9 -> TRUE | AE9: 1 | AH9: 160 | AI9: 160
A10: 255 | B10: 140 | C10: 255 | D10: 110 | E10: 136 | F10: 133 | G10: 156 | H10: 131 | I10: 255 | J10: 250 | N10: {=MMULT(A10:H10,$K$2:$K$9)} -> 29472 | O10: =IF(_xlfn.BITAND(N10,128), 1, 0) -> 0 | P10: 115 | Q10: =P10+O10 -> 115 | R10: {=INDEX(Sigmoid!$1:$1,Q10)} -> 107 | S10: {=MMULT(A10:H10,$L$2:$L$9)} -> 19599 | T10: =IF(_xlfn.BITAND(S10,128), 1, 0) -> 1 | U10: 76 | V10: =U10+T10 -> 77 | W10: {=INDEX(Sigmoid!$1:$1, V10)} -> 58 | X10: =255*$M$2 +R10*$M$3 +W10*$M$4 -> 37350 | Y10: =IF(_xlfn.BITAND(X10,128), 1, 0) -> 1 | Z10: =_xlfn.BITRSHIFT(X10, 8) + Y10 -> 146 | AA10: =DEC2HEX(Z10,2) -> 92 | AB10: =IF(Z10 < 128, 0, 1) -> 1 | AC10: 1 | AD10: =AB10=AC10 -> TRUE | AE10: 1 | AH10: 146 | AI10: 146
A11: 255 | B11: 73 | C11: 90 | D11: 164 | E11: 118 | F11: 75 | G11: 121 | H11: 111 | I11: 159 | J11: 140 | N11: {=MMULT(A11:H11,$K$2:$K$9)} -> 22889 | O11: =IF(_xlfn.BITAND(N11,128), 1, 0) -> 0 | P11: 89 | Q11: =P11+O11 -> 89 | R11: {=INDEX(Sigmoid!$1:$1,Q11)} -> 72 | S11: {=MMULT(A11:H11,$L$2:$L$9)} -> 15950 | T11: =IF(_xlfn.BITAND(S11,128), 1, 0) -> 0 | U11: 62 | V11: =U11+T11 -> 62 | W11: {=INDEX(Sigmoid!$1:$1, V11)} -> 44 | X11: =255*$M$2 +R11*$M$3 +W11*$M$4 -> 32800 | Y11: =IF(_xlfn.BITAND(X11,128), 1, 0) -> 0 | Z11: =_xlfn.BITRSHIFT(X11, 8) + Y11 -> 128 | AA11: =DEC2HEX(Z11,2) -> 80 | AB11: =IF(Z11 < 128, 0, 1) -> 1 | AC11: 0 | AD11: =AB11=AC11 -> FALSE | AE11: 1 | AH11: 128 | AI11: 128
A12: 255 | B12: 16 | C12: 93 | D12: 187 | E12: 88 | F12: 162 | G12: 101 | H12: 27 | I12: 250 | J12: 176 | N12: {=MMULT(A12:H12,$K$2:$K$9)} -> 19247 | O12: =IF(_xlfn.BITAND(N12,128), 1, 0) -> 0 | P12: 75 | Q12: =P12+O12 -> 75 | R12: {=INDEX(Sigmoid!$1:$1,Q12)} -> 56 | S12: {=MMULT(A12:H12,$L$2:$L$9)} -> 13986 | T12: =IF(_xlfn.BITAND(S12,128), 1, 0) -> 1 | U12: 54 | V12: =U12+T12 -> 55 | W12: {=INDEX(Sigmoid!$1:$1, V12)} -> 38 | X12: =255*$M$2 +R12*$M$3 +W12*$M$4 -> 30800 | Y12: =IF(_xlfn.BITAND(X12,128), 1, 0) -> 0 | Z12: =_xlfn.BITRSHIFT(X12, 8) + Y12 -> 120 | AA12: =DEC2HEX(Z12,2) -> 78 | AB12: =IF(Z12 < 128, 0, 1) -> 0 | AC12: 0 | AD12: =AB12=AC12 -> TRUE | AE12: 1 | AH12: 121 | AI12: 120
A13: 255 | B13: 31 | C13: 110 | D13: 120 | E13: 77 | F13: 166 | G13: 101 | H13: 45 | I13: 140 | J13: 121 | N13: {=MMULT(A13:H13,$K$2:$K$9)} -> 18436 | O13: =IF(_xlfn.BITAND(N13,128), 1, 0) -> 0 | P13: 72 | Q13: =P13+O13 -> 72 | R13: {=INDEX(Sigmoid!$1:$1,Q13)} -> 53 | S13: {=MMULT(A13:H13,$L$2:$L$9)} -> 13527 | T13: =IF(_xlfn.BITAND(S13,128), 1, 0) -> 1 | U13: 52 | V13: =U13+T13 -> 53 | W13: {=INDEX(Sigmoid!$1:$1, V13)} -> 36 | X13: =255*$M$2 +R13*$M$3 +W13*$M$4 -> 30250 | Y13: =IF(_xlfn.BITAND(X13,128), 1, 0) -> 0 | Z13: =_xlfn.BITRSHIFT(X13, 8) + Y13 -> 118 | AA13: =DEC2HEX(Z13,2) -> 76 | AB13: =IF(Z13 < 128, 0, 1) -> 0 | AC13: 0 | AD13: =AB13=AC13 -> TRUE | AE13: 1 | AH13: 118 | AI13: 118
A14: 255 | B14: 183 | C14: 181 | D14: 155 | E14: 175 | F14: 135 | G14: 211 | H14: 185 | I14: 176 | J14: 183 | N14: {=MMULT(A14:H14,$K$2:$K$9)} -> 32427 | O14: =IF(_xlfn.BITAND(N14,128), 1, 0) -> 1 | P14: 126 | Q14: =P14+O14 -> 127 | R14: {=INDEX(Sigmoid!$1:$1,Q14)} -> 125 | S14: {=MMULT(A14:H14,$L$2:$L$9)} -> 24119 | T14: =IF(_xlfn.BITAND(S14,128), 1, 0) -> 0 | U14: 94 | V14: =U14+T14 -> 94 | W14: {=INDEX(Sigmoid!$1:$1, V14)} -> 78 | X14: =255*$M$2 +R14*$M$3 +W14*$M$4 -> 42250 | Y14: =IF(_xlfn.BITAND(X14,128), 1, 0) -> 0 | Z14: =_xlfn.BITRSHIFT(X14, 8) + Y14 -> 165 | AA14: =DEC2HEX(Z14,2) -> A5 | AB14: =IF(Z14 < 128, 0, 1) -> 1 | AC14: 1 | AD14: =AB14=AC14 -> TRUE | AE14: 1 | AH14: 165 | AI14: 165
A15: 255 | B15: 129 | C15: 193 | D15: 104 | E15: 159 | F15: 184 | G15: 183 | H15: 161 | I15: 121 | J15: 138 | N15: {=MMULT(A15:H15,$K$2:$K$9)} -> 28735 | O15: =IF(_xlfn.BITAND(N15,128), 1, 0) -> 0 | P15: 112 | Q15: =P15+O15 -> 112 | R15: {=INDEX(Sigmoid!$1:$1,Q15)} -> 102 | S15: {=MMULT(A15:H15,$L$2:$L$9)} -> 21917 | T15: =IF(_xlfn.BITAND(S15,128), 1, 0) -> 1 | U15: 85 | V15: =U15+T15 -> 86 | W15: {=INDEX(Sigmoid!$1:$1, V15)} -> 68 | X15: =255*$M$2 +R15*$M$3 +W15*$M$4 -> 39100 | Y15: =IF(_xlfn.BITAND(X15,128), 1, 0) -> 1 | Z15: =_xlfn.BITRSHIFT(X15, 8) + Y15 -> 153 | AA15: =DEC2HEX(Z15,2) -> 99 | AB15: =IF(Z15 < 128, 0, 1) -> 1 | AC15: 1 | AD15: =AB15=AC15 -> TRUE | AE15: 1 | AH15: 153 | AI15: 153
A16: 255 | B16: 190 | C16: 183 | D16: 143 | E16: 124 | F16: 139 | G16: 138 | H16: 145 | I16: 183 | J16: 167 | N16: {=MMULT(A16:H16,$K$2:$K$9)} -> 29355 | O16: =IF(_xlfn.BITAND(N16,128), 1, 0) -> 1 | P16: 114 | Q16: =P16+O16 -> 115 | R16: {=INDEX(Sigmoid!$1:$1,Q16)} -> 107 | S16: {=MMULT(A16:H16,$L$2:$L$9)} -> 21549 | T16: =IF(_xlfn.BITAND(S16,128), 1, 0) -> 0 | U16: 84 | V16: =U16+T16 -> 84 | W16: {=INDEX(Sigmoid!$1:$1, V16)} -> 66 | X16: =255*$M$2 +R16*$M$3 +W16*$M$4 -> 38950 | Y16: =IF(_xlfn.BITAND(X16,128), 1, 0) -> 0 | Z16: =_xlfn.BITRSHIFT(X16, 8) + Y16 -> 152 | AA16: =DEC2HEX(Z16,2) -> 98 | AB16: =IF(Z16 < 128, 0, 1) -> 1 | AC16: 1 | AD16: =AB16=AC16 -> TRUE | AE16: 1 | AH16: 152 | AI16: 152
A17: 255 | B17: 79 | C17: 113 | D17: 115 | E17: 111 | F17: 164 | G17: 101 | H17: 88 | I17: 138 | J17: 158 | N17: {=MMULT(A17:H17,$K$2:$K$9)} -> 21448 | O17: =IF(_xlfn.BITAND(N17,128), 1, 0) -> 1 | P17: 83 | Q17: =P17+O17 -> 84 | R17: {=INDEX(Sigmoid!$1:$1,Q17)} -> 66 | S17: {=MMULT(A17:H17,$L$2:$L$9)} -> 16192 | T17: =IF(_xlfn.BITAND(S17,128), 1, 0) -> 0 | U17: 63 | V17: =U17+T17 -> 63 | W17: {=INDEX(Sigmoid!$1:$1, V17)} -> 44 | X17: =255*$M$2 +R17*$M$3 +W17*$M$4 -> 32500 | Y17: =IF(_xlfn.BITAND(X17,128), 1, 0) -> 1 | Z17: =_xlfn.BITRSHIFT(X17, 8) + Y17 -> 127 | AA17: =DEC2HEX(Z17,2) -> 7F | AB17: =IF(Z17 < 128, 0, 1) -> 0 | AC17: 0 | AD17: =AB17=AC17 -> TRUE | AE17: 1 | AH17: 127 | AI17: 127
A18: 255 | B18: 213 | C18: 213 | D18: 149 | E18: 159 | F18: 133 | G18: 199 | H18: 183 | I18: 255 | J18: 172 | N18: {=MMULT(A18:H18,$K$2:$K$9)} -> 33457 | O18: =IF(_xlfn.BITAND(N18,128), 1, 0) -> 1 | P18: 130 | Q18: =P18+O18 -> 131 | R18: {=INDEX(Sigmoid!$1:$1,Q18)} -> 130 | S18: {=MMULT(A18:H18,$L$2:$L$9)} -> 24425 | T18: =IF(_xlfn.BITAND(S18,128), 1, 0) -> 0 | U18: 95 | V18: =U18+T18 -> 95 | W18: {=INDEX(Sigmoid!$1:$1, V18)} -> 79 | X18: =255*$M$2 +R18*$M$3 +W18*$M$4 -> 42700 | Y18: =IF(_xlfn.BITAND(X18,128), 1, 0) -> 1 | Z18: =_xlfn.BITRSHIFT(X18, 8) + Y18 -> 167 | AA18: =DEC2HEX(Z18,2) -> A7 | AB18: =IF(Z18 < 128, 0, 1) -> 1 | AC18: 1 | AD18: =AB18=AC18 -> TRUE | AE18: 1 | AH18: 167 | AI18: 167
A19: 255 | B19: 13 | C19: 94 | D19: 127 | E19: 146 | F19: 132 | G19: 150 | H19: 89 | I19: 167 | J19: 134 | N19: {=MMULT(A19:H19,$K$2:$K$9)} -> 20860 | O19: =IF(_xlfn.BITAND(N19,128), 1, 0) -> 0 | P19: 81 | Q19: =P19+O19 -> 81 | R19: {=INDEX(Sigmoid!$1:$1,Q19)} -> 62 | S19: {=MMULT(A19:H19,$L$2:$L$9)} -> 14827 | T19: =IF(_xlfn.BITAND(S19,128), 1, 0) -> 1 | U19: 57 | V19: =U19+T19 -> 58 | W19: {=INDEX(Sigmoid!$1:$1, V19)} -> 40 | X19: =255*$M$2 +R19*$M$3 +W19*$M$4 -> 31500 | Y19: =IF(_xlfn.BITAND(X19,128), 1, 0) -> 0 | Z19: =_xlfn.BITRSHIFT(X19, 8) + Y19 -> 123 | AA19: =DEC2HEX(Z19,2) -> 7B | AB19: =IF(Z19 < 128, 0, 1) -> 0 | AC19: 0 | AD19: =AB19=AC19 -> TRUE | AE19: 1 | AH19: 123 | AI19: 123
A20: 255 | B20: 103 | C20: 175 | D20: 164 | E20: 139 | F20: 187 | G20: 147 | H20: 128 | I20: 158 | J20: 172 | N20: {=MMULT(A20:H20,$K$2:$K$9)} -> 27576 | O20: =IF(_xlfn.BITAND(N20,128), 1, 0) -> 1 | P20: 107 | Q20: =P20+O20 -> 108 | R20: {=INDEX(Sigmoid!$1:$1,Q20)} -> 97 | S20: {=MMULT(A20:H20,$L$2:$L$9)} -> 21156 | T20: =IF(_xlfn.BITAND(S20,128), 1, 0) -> 1 | U20: 82 | V20: =U20+T20 -> 83 | W20: {=INDEX(Sigmoid!$1:$1, V20)} -> 64 | X20: =255*$M$2 +R20*$M$3 +W20*$M$4 -> 38050 | Y20: =IF(_xlfn.BITAND(X20,128), 1, 0) -> 1 | Z20: =_xlfn.BITRSHIFT(X20, 8) + Y20 -> 149 | AA20: =DEC2HEX(Z20,2) -> 95 | AB20: =IF(Z20 < 128, 0, 1) -> 1 | AC20: 1 | AD20: =AB20=AC20 -> TRUE | AE20: 1 | AH20: 149 | AI20: 149
A21: 255 | B21: 42 | C21: 82 | D21: 104 | E21: 83 | F21: 167 | G21: 50 | H21: 71 | I21: 172 | J21: 161 | N21: {=MMULT(A21:H21,$K$2:$K$9)} -> 17627 | O21: =IF(_xlfn.BITAND(N21,128), 1, 0) -> 1 | P21: 68 | Q21: =P21+O21 -> 69 | R21: {=INDEX(Sigmoid!$1:$1,Q21)} -> 50 | S21: {=MMULT(A21:H21,$L$2:$L$9)} -> 13886 | T21: =IF(_xlfn.BITAND(S21,128), 1, 0) -> 0 | U21: 54 | V21: =U21+T21 -> 54 | W21: {=INDEX(Sigmoid!$1:$1, V21)} -> 37 | X21: =255*$M$2 +R21*$M$3 +W21*$M$4 -> 30300 | Y21: =IF(_xlfn.BITAND(X21,128), 1, 0) -> 0 | Z21: =_xlfn.BITRSHIFT(X21, 8) + Y21 -> 118 | AA21: =DEC2HEX(Z21,2) -> 76 | AB21: =IF(Z21 < 128, 0, 1) -> 0 | AC21: 0 | AD21: =AB21=AC21 -> TRUE | AE21: 1 | AH21: 119 | AI21: 118
... A65: 255 | B65: 19 | C65: 56 | D65: 140 | E65: 139 | F65: 217 | G65: 161 | H65: 51 | I65: 126 | J65: 73 | N65: {=MMULT(A65:H65,$K$2:$K$9)} -> 19273 | O65: =IF(_xlfn.BITAND(N65,128), 1, 0) -> 0 | P65: 75 | Q65: =P65+O65 -> 75 | R65: {=INDEX(Sigmoid!$1:$1,Q65)} -> 56 | S65: {=MMULT(A65:H65,$L$2:$L$9)} -> 15807 | T65: =IF(_xlfn.BITAND(S65,128), 1, 0) -> 1 | U65: 61 | V65: =U65+T65 -> 62 | W65: {=INDEX(Sigmoid!$1:$1, V65)} -> 44 | X65: =255*$M$2 +R65*$M$3 +W65*$M$4 -> 32000 | Y65: =IF(_xlfn.BITAND(X65,128), 1, 0) -> 0 | Z65: =_xlfn.BITRSHIFT(X65, 8) + Y65 -> 125 | AA65: =DEC2HEX(Z65,2) -> 7D | AB65: =IF(Z65 < 128, 0, 1) -> 0 | AC65: 0 | AD65: =AB65=AC65 -> TRUE | AE65: 1 | AH65: 125 | AI65: 125
I66: 255 | J66: 90
I67: 140 | J67: 164
I68: 255 | J68: 118
I69: 110 | J69: 75
I70: 136 | J70: 121
I71: 133 | J71: 111
I72: 156 | J72: 16
I73: 131 | J73: 93
I74: 255 | J74: 187
I75: 73 | J75: 88
I76: 90 | J76: 162
I77: 164 | J77: 101
... I449: 56 | J449: 51
I450: 255
I451: 37
I452: 70
I453: 131
I454: 53
...

Sheet X - MLP Prediction
B1: input V | K1: Weight N1, hidden | L1: Weight N2, hidden | M1: w, output | N1: N1 | O1: sigmoid N1 | R1: sigmoid N2 | S1: Solution | T1: Prediction | U1: Actual | W1: accuracy
A2: 255 | B2: 44 | C2: 90 | D2: 0 | E2: 0 | F2: 24 | G2: 81 | H2: 22 | K2: 26 | L2: 6 | M2: 80 | N2: {=_xlfn.BITRSHIFT($K$2+MMULT(B2:H65, K3:K9),8)} -> 21 | O2: {=INDEX(Sigmoid!$1:$1, N2)} -> 18 | Q2: {=_xlfn.BITRSHIFT($L$2+MMULT(B2:H65, L3:L9),8)} -> 14 | R2: {=INDEX(Sigmoid!$1:$1, Q2)} -> 16 | S2: =_xlfn.BITRSHIFT($M$2+O2*$M$3 +R2*$M$4, 8) -> 16 | T2: 0 | U2: 0 | V2: 1 | W2: 0.921875
A3: 255 | B3: 159 | C3: 250 | D3: 140 | E3: 176 | F3: 121 | G3: 183 | H3: 138 | K3: 25 | L3: 18 | M3: 50 | N3: 99 | O3: {=INDEX(Sigmoid!$1:$1, N3)} -> 84 | Q3: 75 | R3: {=INDEX(Sigmoid!$1:$1, Q3)} -> 56 | S3: =_xlfn.BITRSHIFT($M$2+O3*$M$3 +R3*$M$4, 8) -> 60 | T3: 1 | U3: 1 | V3: 1
A4: 255 | B4: 167 | C4: 158 | D4: 172 | E4: 134 | F4: 172 | G4: 161 | H4: 118 | K4: 31 | L4: 6 | M4: 200 | N4: 86 | O4: {=INDEX(Sigmoid!$1:$1, N4)} -> 68 | Q4: 78 | R4: {=INDEX(Sigmoid!$1:$1, Q4)} -> 59 | S4: =_xlfn.BITRSHIFT($M$2+O4*$M$3 +R4*$M$4, 8) -> 59 | T4: 1 | U4: 1 | V4: 1
A5: 255 | B5: 130 | C5: 178 | D5: 136 | E5: 120 | F5: 135 | G5: 121 | H5: 86 | K5: 29 | L5: 26 | N5: 74 | O5: {=INDEX(Sigmoid!$1:$1, N5)} -> 55 | Q5: 61 | R5: {=INDEX(Sigmoid!$1:$1, Q5)} -> 43 | S5: =_xlfn.BITRSHIFT($M$2+O5*$M$3 +R5*$M$4, 8) -> 44 | T5: 0 | U5: 1 | V5: 0
A6: 255 | B6: 34 | C6: 112 | D6: 142 | E6: 112 | F6: 163 | G6: 159 | H6: 43 | K6: 22 | L6: 1 | N6: 54 | O6: {=INDEX(Sigmoid!$1:$1, N6)} -> 37 | Q6: 50 | R6: {=INDEX(Sigmoid!$1:$1, Q6)} -> 34 | S6: =_xlfn.BITRSHIFT($M$2+O6*$M$3 +R6*$M$4, 8) -> 34 | T6: 0 | U6: 0 | V6: 1
A7: 255 | B7: 63 | C7: 28 | D7: 145 | E7: 126 | F7: 190 | G7: 165 | H7: 66 | K7: 1 | L7: 28 | N7: 51 | O7: {=INDEX(Sigmoid!$1:$1, N7)} -> 35 | Q7: 58 | R7: {=INDEX(Sigmoid!$1:$1, Q7)} -> 40 | S7: =_xlfn.BITRSHIFT($M$2+O7*$M$3 +R7*$M$4, 8) -> 38 | T7: 0 | U7: 0 | V7: 1
A8: 255 | B8: 88 | C8: 214 | D8: 157 | E8: 140 | F8: 205 | G8: 174 | H8: 128 | K8: 11 | L8: 9 | N8: 85 | O8: {=INDEX(Sigmoid!$1:$1, N8)} -> 67 | Q8: 78 | R8: {=INDEX(Sigmoid!$1:$1, Q8)} -> 59 | S8: =_xlfn.BITRSHIFT($M$2+O8*$M$3 +R8*$M$4, 8) -> 59 | T8: 1 | U8: 1 | V8: 1
A9: 255 | B9: 185 | C9: 203 | D9: 170 | E9: 110 | F9: 211 | G9: 138 | H9: 126 | K9: 26 | L9: 45 | N9: 91 | O9: {=INDEX(Sigmoid!$1:$1, N9)} -> 74 | Q9: 85 | R9: {=INDEX(Sigmoid!$1:$1, Q9)} -> 67 | S9: =_xlfn.BITRSHIFT($M$2+O9*$M$3 +R9*$M$4, 8) -> 67 | T9: 1 | U9: 1 | V9: 1
A10: 255 | B10: 140 | C10: 255 | D10: 110 | E10: 136 | F10: 133 | G10: 156 | H10: 131 | N10: 89 | O10: {=INDEX(Sigmoid!$1:$1, N10)} -> 72 | Q10: 70 | R10: {=INDEX(Sigmoid!$1:$1, Q10)} -> 51 | S10: =_xlfn.BITRSHIFT($M$2+O10*$M$3 +R10*$M$4, 8) -> 54 | T10: 1 | U10: 1 | V10: 1
A11: 255 | B11: 73 | C11: 90 | D11: 164 | E11: 118 | F11: 75 | G11: 121 | H11: 111 | K11: {=MMULT(A2:H2,K2:K9)} -> 12007 | N11: 63 | O11: {=INDEX(Sigmoid!$1:$1, N11)} -> 44 | Q11: 56 | R11: {=INDEX(Sigmoid!$1:$1, Q11)} -> 39 | S11: =_xlfn.BITRSHIFT($M$2+O11*$M$3 +R11*$M$4, 8) -> 39 | T11: 0 | U11: 0 | V11: 1
A12: 255 | B12: 16 | C12: 93 | D12: 187 | E12: 88 | F12: 162 | G12: 101 | H12: 27 | N12: 49 | O12: {=INDEX(Sigmoid!$1:$1, N12)} -> 34 | Q12: 48 | R12: {=INDEX(Sigmoid!$1:$1, Q12)} -> 33 | S12: =_xlfn.BITRSHIFT($M$2+O12*$M$3 +R12*$M$4, 8) -> 32 | T12: 0 | U12: 0 | V12: 1
A13: 255 | B13: 31 | C13: 110 | D13: 120 | E13: 77 | F13: 166 | G13: 101 | H13: 45 | N13: 46 | O13: {=INDEX(Sigmoid!$1:$1, N13)} -> 32 | Q13: 46 | R13: {=INDEX(Sigmoid!$1:$1, Q13)} -> 32 | S13: =_xlfn.BITRSHIFT($M$2+O13*$M$3 +R13*$M$4, 8) -> 31 | T13: 0 | U13: 0 | V13: 1
A14: 255 | B14: 183 | C14: 181 | D14: 155 | E14: 175 | F14: 135 | G14: 211 | H14: 185 | N14: 100 | O14: {=INDEX(Sigmoid!$1:$1, N14)} -> 86 | Q14: 88 | R14: {=INDEX(Sigmoid!$1:$1, Q14)} -> 70 | S14: =_xlfn.BITRSHIFT($M$2+O14*$M$3 +R14*$M$4, 8) -> 71 | T14: 1 | U14: 1 | V14: 1
A15: 255 | B15: 129 | C15: 193 | D15: 104 | E15: 159 | F15: 184 | G15: 183 | H15: 161 | N15: 86 | O15: {=INDEX(Sigmoid!$1:$1, N15)} -> 68 | Q15: 79 | R15: {=INDEX(Sigmoid!$1:$1, Q15)} -> 60 | S15: =_xlfn.BITRSHIFT($M$2+O15*$M$3 +R15*$M$4, 8) -> 60 | T15: 1 | U15: 1 | V15: 1
A16: 255 | B16: 190 | C16: 183 | D16: 143 | E16: 124 | F16: 139 | G16: 138 | H16: 145 | N16: 88 | O16: {=INDEX(Sigmoid!$1:$1, N16)} -> 70 | Q16: 78 | R16: {=INDEX(Sigmoid!$1:$1, Q16)} -> 59 | S16: =_xlfn.BITRSHIFT($M$2+O16*$M$3 +R16*$M$4, 8) -> 60 | T16: 1 | U16: 1 | V16: 1
A17: 255 | B17: 79 | C17: 113 | D17: 115 | E17: 111 | F17: 164 | G17: 101 | H17: 88 | N17: 57 | O17: {=INDEX(Sigmoid!$1:$1, N17)} -> 39 | Q17: 57 | R17: {=INDEX(Sigmoid!$1:$1, Q17)} -> 39 | S17: =_xlfn.BITRSHIFT($M$2+O17*$M$3 +R17*$M$4, 8) -> 38 | T17: 0 | U17: 0 | V17: 1
A18: 255 | B18: 213 | C18: 213 | D18: 149 | E18: 159 | F18: 133 | G18: 199 | H18: 183 | N18: 104 | O18: {=INDEX(Sigmoid!$1:$1, N18)} -> 91 | Q18: 89 | R18: {=INDEX(Sigmoid!$1:$1, Q18)} -> 72 | S18: =_xlfn.BITRSHIFT($M$2+O18*$M$3 +R18*$M$4, 8) -> 74 | T18: 1 | U18: 1 | V18: 1
A19: 255 | B19: 13 | C19: 94 | D19: 127 | E19: 146 | F19: 132 | G19: 150 | H19: 89 | N19: 55 | O19: {=INDEX(Sigmoid!$1:$1, N19)} -> 38 | Q19: 51 | R19: {=INDEX(Sigmoid!$1:$1, Q19)} -> 35 | S19: =_xlfn.BITRSHIFT($M$2+O19*$M$3 +R19*$M$4, 8) -> 35 | T19: 0 | U19: 0 | V19: 1
A20: 255 | B20: 103 | C20: 175 | D20: 164 | E20: 139 | F20: 187 | G20: 147 | H20: 128 | N20: 81 | O20: {=INDEX(Sigmoid!$1:$1, N20)} -> 62 | Q20: 76 | R20: {=INDEX(Sigmoid!$1:$1, Q20)} -> 57 | S20: =_xlfn.BITRSHIFT($M$2+O20*$M$3 +R20*$M$4, 8) -> 56 | T20: 1 | U20: 1 | V20: 1
A21: 255 | B21: 42 | C21: 82 | D21: 104 | E21: 83 | F21: 167 | G21: 50 | H21: 71 | N21: 43 | O21: {=INDEX(Sigmoid!$1:$1, N21)} -> 30 | Q21: 48 | R21: {=INDEX(Sigmoid!$1:$1, Q21)} -> 33 | S21: =_xlfn.BITRSHIFT($M$2+O21*$M$3 +R21*$M$4, 8) -> 31 | T21: 0 | U21: 0 | V21: 1
A22: 255 | B22: 26 | C22: 90 | D22: 109 | E22: 143 | F22: 135 | G22: 220 | H22: 106 | N22: 58 | O22: {=INDEX(Sigmoid!$1:$1, N22)} -> 40 | Q22: 56 | R22: {=INDEX(Sigmoid!$1:$1, Q22)} -> 39 | S22: =_xlfn.BITRSHIFT($M$2+O22*$M$3 +R22*$M$4, 8) -> 38 | T22: 0 | U22: 0 | V22: 1
A23: 255 | B23: 69 | C23: 90 | D23: 101 | E23: 180 | F23: 125 | G23: 222 | H23: 108 | N23: 65 | O23: {=INDEX(Sigmoid!$1:$1, N23)} -> 46 | Q23: 58 | R23: {=INDEX(Sigmoid!$1:$1, Q23)} -> 40 | S23: =_xlfn.BITRSHIFT($M$2+O23*$M$3 +R23*$M$4, 8) -> 40 | T23: 0 | U23: 1 | V23: 0
... A65: 255 | B65: 19 | C65: 56 | D65: 140 | E65: 139 | F65: 217 | G65: 161 | H65: 51 | N65: 49 | O65: {=INDEX(Sigmoid!$1:$1, N65)} -> 34 | Q65: 55 | R65: {=INDEX(Sigmoid!$1:$1, Q65)} -> 38 | S65: =_xlfn.BITRSHIFT($M$2+O65*$M$3 +R65*$M$4, 8) -> 36 | T65: 0 | U65: 0 | V65: 1

Sheet test_inputs
A1: 64 by 8 | B1: 64 by 8 | C1: 64 by 7 | D1: 64 by 7 | E1: 3 test cases + weights + sigmoid | F1: weights | G1: weights input | H1: sigmoid dec | I1: sigmoid input | J1: Sol v4 | K1: SW INPUT, A (7*64) + weights + expected result | L1: HLS input (64*8 + weights)
A2: {=_xlfn.TOCOL('X - MLP Prediction'!A2:H65)} -> 255 | B2: =DEC2HEX(A2, 2) -> FF | C2: 44 | D2: =DEC2HEX(C2, 2) -> 2C | E2: 01 | F2: 26 | G2: =DEC2HEX(F2, 2) -> 1A | H2: {=_xlfn.TOCOL(Sigmoid!A1:IV1)} -> 12 | I2: =DEC2HEX(H2, 2) -> 0C | J2: {='X - MLP v4'!AA2:AA65} -> 64 | K2: {=_xlfn.TOCOL(D2:D513)} -> 2C | L2: {=B2:B513} -> FF
A3: 44 | B3: =DEC2HEX(A3, 2) -> 2C | C3: 90 | D3: =DEC2HEX(C3, 2) -> 5A | E3: 2C | F3: 25 | G3: =DEC2HEX(F3, 2) -> 19 | H3: 12 | I3: =DEC2HEX(H3, 2) -> 0C | J3: 99 | K3: 5A | L3: 2C
A4: 90 | B4: =DEC2HEX(A4, 2) -> 5A | C4: 0 | D4: =DEC2HEX(C4, 2) -> 00 | E4: 5A | F4: 31 | G4: =DEC2HEX(F4, 2) -> 1F | H4: 12 | I4: =DEC2HEX(H4, 2) -> 0C | J4: 98 | K4: 00 | L4: 5A
A5: 0 | B5: =DEC2HEX(A5, 2) -> 00 | C5: 0 | D5: =DEC2HEX(C5, 2) -> 00 | E5: 00 | F5: 29 | G5: =DEC2HEX(F5, 2) -> 1D | H5: 12 | I5: =DEC2HEX(H5, 2) -> 0C | J5: 87 | K5: 00 | L5: 00
A6: 0 | B6: =DEC2HEX(A6, 2) -> 00 | C6: 24 | D6: =DEC2HEX(C6, 2) -> 18 | E6: 00 | F6: 22 | G6: =DEC2HEX(F6, 2) -> 16 | H6: 13 | I6: =DEC2HEX(H6, 2) -> 0D | J6: 7A | K6: 18 | L6: 00
A7: 24 | B7: =DEC2HEX(A7, 2) -> 18 | C7: 81 | D7: =DEC2HEX(C7, 2) -> 51 | E7: 18 | F7: 1 | G7: =DEC2HEX(F7, 2) -> 01 | H7: 13 | I7: =DEC2HEX(H7, 2) -> 0D | J7: 7E | K7: 51 | L7: 18
A8: 81 | B8: =DEC2HEX(A8, 2) -> 51 | C8: 22 | D8: =DEC2HEX(C8, 2) -> 16 | E8: 51 | F8: 11 | G8: =DEC2HEX(F8, 2) -> 0B | H8: 13 | I8: =DEC2HEX(H8, 2) -> 0D | J8: 98 | K8: 16 | L8: 51
A9: 22 | B9: =DEC2HEX(A9, 2) -> 16 | C9: 159 | D9: =DEC2HEX(C9, 2) -> 9F | E9: 16 | F9: 26 | G9: =DEC2HEX(F9, 2) -> 1A | H9: 14 | I9: =DEC2HEX(H9, 2) -> 0E | J9: A0 | K9: 9F | L9: 16
A10: 255 | B10: =DEC2HEX(A10, 2) -> FF | C10: 250 | D10: =DEC2HEX(C10, 2) -> FA | E10: 01 | F10: 6 | G10: =DEC2HEX(F10, 2) -> 06 | H10: 14 | I10: =DEC2HEX(H10, 2) -> 0E | J10: 92 | K10: FA | L10: FF
A11: 159 | B11: =DEC2HEX(A11, 2) -> 9F | C11: 140 | D11: =DEC2HEX(C11, 2) -> 8C | E11: 9F | F11: 18 | G11: =DEC2HEX(F11, 2) -> 12 | H11: 14 | I11: =DEC2HEX(H11, 2) -> 0E | J11: 80 | K11: 8C | L11: 9F
A12: 250 | B12: =DEC2HEX(A12, 2) -> FA | C12: 176 | D12: =DEC2HEX(C12, 2) -> B0 | E12: FA | F12: 6 | G12: =DEC2HEX(F12, 2) -> 06 | H12: 15 | I12: =DEC2HEX(H12, 2) -> 0F | J12: 78 | K12: B0 | L12: FA
A13: 140 | B13: =DEC2HEX(A13, 2) -> 8C | C13: 121 | D13: =DEC2HEX(C13, 2) -> 79 | E13: 8C | F13: 26 | G13: =DEC2HEX(F13, 2) -> 1A | H13: 15 | I13: =DEC2HEX(H13, 2) -> 0F | J13: 76 | K13: 79 | L13: 8C
A14: 176 | B14: =DEC2HEX(A14, 2) -> B0 | C14: 183 | D14: =DEC2HEX(C14, 2) -> B7 | E14: B0 | F14: 1 | G14: =DEC2HEX(F14, 2) -> 01 | H14: 15 | I14: =DEC2HEX(H14, 2) -> 0F | J14: A5 | K14: B7 | L14: B0
... A20: 158 | B20: =DEC2HEX(A20, 2) -> 9E | C20: 172 | D20: =DEC2HEX(C20, 2) -> AC | E20: 9E | F20: 200 | G20: =DEC2HEX(F20, 2) -> C8 | H20: 18 | I20: =DEC2HEX(H20, 2) -> 12 | J20: 95 | K20: AC | L20: 9E
A21: 172 | B21: =DEC2HEX(A21, 2) -> AC | C21: 161 | D21: =DEC2HEX(C21, 2) -> A1 | E21: AC | H21: 18 | I21: =DEC2HEX(H21, 2) -> 12 | J21: 76 | K21: A1 | L21: AC
A22: 134 | B22: =DEC2HEX(A22, 2) -> 86 | C22: 118 | D22: =DEC2HEX(C22, 2) -> 76 | E22: 86 | H22: 18 | I22: =DEC2HEX(H22, 2) -> 12 | J22: 7F | K22: 76 | L22: 86
A23: 172 | B23: =DEC2HEX(A23, 2) -> AC | C23: 130 | D23: =DEC2HEX(C23, 2) -> 82 | E23: AC | H23: 19 | I23: =DEC2HEX(H23, 2) -> 13 | J23: 81 | K23: 82 | L23: AC
A24: 161 | B24: =DEC2HEX(A24, 2) -> A1 | C24: 178 | D24: =DEC2HEX(C24, 2) -> B2 | E24: A1 | H24: 19 | I24: =DEC2HEX(H24, 2) -> 13 | J24: 98 | K24: B2 | L24: A1
A25: 118 | B25: =DEC2HEX(A25, 2) -> 76 | C25: 136 | D25: =DEC2HEX(C25, 2) -> 88 | E25: 76 | H25: 20 | I25: =DEC2HEX(H25, 2) -> 14 | J25: 71 | K25: 88 | L25: 76
A26: 255 | B26: =DEC2HEX(A26, 2) -> FF | C26: 120 | D26: =DEC2HEX(C26, 2) -> 78 | E26: 1A | H26: 20 | I26: =DEC2HEX(H26, 2) -> 14 | J26: 92 | K26: 78 | L26: FF
A27: 130 | B27: =DEC2HEX(A27, 2) -> 82 | C27: 135 | D27: =DEC2HEX(C27, 2) -> 87 | E27: 19 | H27: 21 | I27: =DEC2HEX(H27, 2) -> 15 | J27: 8C | K27: 87 | L27: 82
A28: 178 | B28: =DEC2HEX(A28, 2) -> B2 | C28: 121 | D28: =DEC2HEX(C28, 2) -> 79 | E28: 1F | H28: 21 | I28: =DEC2HEX(H28, 2) -> 15 | J28: 9D | K28: 79 | L28: B2
A29: 136 | B29: =DEC2HEX(A29, 2) -> 88 | C29: 86 | D29: =DEC2HEX(C29, 2) -> 56 | E29: 1D | H29: 21 | I29: =DEC2HEX(H29, 2) -> 15 | J29: 90 | K29: 56 | L29: 88
A30: 120 | B30: =DEC2HEX(A30, 2) -> 78 | C30: 34 | D30: =DEC2HEX(C30, 2) -> 22 | E30: 16 | H30: 22 | I30: =DEC2HEX(H30, 2) -> 16 | J30: 77 | K30: 22 | L30: 78
A31: 135 | B31: =DEC2HEX(A31, 2) -> 87 | C31: 112 | D31: =DEC2HEX(C31, 2) -> 70 | E31: 01 | H31: 22 | I31: =DEC2HEX(H31, 2) -> 16 | J31: 6F | K31: 70 | L31: 87
A32: 121 | B32: =DEC2HEX(A32, 2) -> 79 | C32: 142 | D32: =DEC2HEX(C32, 2) -> 8E | E32: 0B | H32: 23 | I32: =DEC2HEX(H32, 2) -> 17 | J32: 77 | K32: 8E | L32: 79
... A65: 126 | B65: =DEC2HEX(A65, 2) -> 7E | C65: 73 | D65: =DEC2HEX(C65, 2) -> 49 | E65: 12 | H65: 45 | I65: =DEC2HEX(H65, 2) -> 2D | J65: 7D | K65: 49 | L65: 7E
A66: 255 | B66: =DEC2HEX(A66, 2) -> FF | C66: 90 | D66: =DEC2HEX(C66, 2) -> 5A | E66: 13 | H66: 46 | I66: =DEC2HEX(H66, 2) -> 2E | K66: 5A | L66: FF
A67: 140 | B67: =DEC2HEX(A67, 2) -> 8C | C67: 164 | D67: =DEC2HEX(C67, 2) -> A4 | E67: 13 | H67: 47 | I67: =DEC2HEX(H67, 2) -> 2F | K67: A4 | L67: 8C
A68: 255 | B68: =DEC2HEX(A68, 2) -> FF | C68: 118 | D68: =DEC2HEX(C68, 2) -> 76 | E68: 14 | H68: 48 | I68: =DEC2HEX(H68, 2) -> 30 | K68: 76 | L68: FF
A69: 110 | B69: =DEC2HEX(A69, 2) -> 6E | C69: 75 | D69: =DEC2HEX(C69, 2) -> 4B | E69: 14 | H69: 49 | I69: =DEC2HEX(H69, 2) -> 31 | K69: 4B | L69: 6E
A70: 136 | B70: =DEC2HEX(A70, 2) -> 88 | C70: 121 | D70: =DEC2HEX(C70, 2) -> 79 | E70: 15 | H70: 50 | I70: =DEC2HEX(H70, 2) -> 32 | K70: 79 | L70: 88
A71: 133 | B71: =DEC2HEX(A71, 2) -> 85 | C71: 111 | D71: =DEC2HEX(C71, 2) -> 6F | E71: 15 | H71: 51 | I71: =DEC2HEX(H71, 2) -> 33 | K71: 6F | L71: 85
A72: 156 | B72: =DEC2HEX(A72, 2) -> 9C | C72: 16 | D72: =DEC2HEX(C72, 2) -> 10 | E72: 15 | H72: 52 | I72: =DEC2HEX(H72, 2) -> 34 | K72: 10 | L72: 9C
A73: 131 | B73: =DEC2HEX(A73, 2) -> 83 | C73: 93 | D73: =DEC2HEX(C73, 2) -> 5D | E73: 16 | H73: 53 | I73: =DEC2HEX(H73, 2) -> 35 | K73: 5D | L73: 83
A74: 255 | B74: =DEC2HEX(A74, 2) -> FF | C74: 187 | D74: =DEC2HEX(C74, 2) -> BB | E74: 16 | H74: 54 | I74: =DEC2HEX(H74, 2) -> 36 | K74: BB | L74: FF
A75: 73 | B75: =DEC2HEX(A75, 2) -> 49 | C75: 88 | D75: =DEC2HEX(C75, 2) -> 58 | E75: 17 | H75: 55 | I75: =DEC2HEX(H75, 2) -> 37 | K75: 58 | L75: 49
A76: 90 | B76: =DEC2HEX(A76, 2) -> 5A | C76: 162 | D76: =DEC2HEX(C76, 2) -> A2 | E76: 17 | H76: 56 | I76: =DEC2HEX(H76, 2) -> 38 | K76: A2 | L76: 5A
A77: 164 | B77: =DEC2HEX(A77, 2) -> A4 | C77: 101 | D77: =DEC2HEX(C77, 2) -> 65 | E77: 18 | H77: 57 | I77: =DEC2HEX(H77, 2) -> 39 | K77: 65 | L77: A4
...

Sheet Sigmoid
A1: 12 | B1: 12 | C1: 12 | D1: 12 | E1: 13 | F1: 13 | G1: 13 | H1: 14 | I1: 14 | J1: 14 | K1: 15 | L1: 15 | M1: 15 | N1: 16 | O1: 16 | P1: 16 | Q1: 17 | R1: 17 | S1: 18 | T1: 18 | U1: 18 | V1: 19 | W1: 19 | X1: 20 | Y1: 20 | Z1: 21 | AA1: 21 | AB1: 21 | AC1: 22 | AD1: 22 | AE1: 23 | AF1: 23 | AG1: 24 | AH1: 24 | AI1: 25 | AJ1: 26 | AK1: 26 | AL1: 27 | AM1: 27 | AN1: 28 | AO1: 28 | AP1: 29 | AQ1: 30 | AR1: 30 | AS1: 31 | AT1: 32 | AU1: 32 | AV1: 33 | AW1: 34 | AX1: 34 | AY1: 35 | AZ1: 36 | BA1: 36 | BB1: 37 | BC1: 38 | BD1: 39 | BE1: 39 | BF1: 40 | BG1: 41 | BH1: 42 | BI1: 43 | BJ1: 44 | BK1: 44 | BL1: 45 | BM1: 46 | BN1: 47 | BO1: 48 | BP1: 49 | BQ1: 50 | BR1: 51 | BS1: 52 | BT1: 53 | BU1: 54 | BV1: 55 | BW1: 56 | BX1: 57 | BY1: 58 | BZ1: 59 | CA1: 60 | CB1: 61 | CC1: 62 | CD1: 63 | CE1: 64 | CF1: 66 | CG1: 67 | CH1: 68 | CI1: 69 | CJ1: 70 | CK1: 72 | CL1: 73 | CM1: 74 | CN1: 75 | CO1: 76 | CP1: 78 | CQ1: 79 | CR1: 80 | CS1: 82 | CT1: 83 | CU1: 84 | CV1: 86 | CW1: 87 | CX1: 88 | CY1: 90 | CZ1: 91 | DA1: 92 | DB1: 94 | DC1: 95 | DD1: 97 | DE1: 98 | DF1: 99 | DG1: 101 | DH1: 102 | DI1: 104 | DJ1: 105 | DK1: 107 | DL1: 108 | DM1: 110 | DN1: 111 | DO1: 113 | DP1: 114 | DQ1: 116 | DR1: 117 | DS1: 119 | DT1: 120 | DU1: 122 | DV1: 123 | DW1: 125 | DX1: 126 | DY1: 128 | DZ1: 129 | EA1: 130 | EB1: 132 | EC1: 133 | ED1: 135 | EE1: 136 | EF1: 138 | EG1: 139 | EH1: 141 | EI1: 142 | EJ1: 144 | EK1: 145 | EL1: 147 | EM1: 148 | EN1: 150 | EO1: 151 | EP1: 153 | EQ1: 154 | ER1: 156 | ES1: 157 | ET1: 158 | EU1: 160 | EV1: 161 | EW1: 163 | EX1: 164 | EY1: 165 | EZ1: 167 | FA1: 168 | FB1: 169 | FC1: 171 | FD1: 172 | FE1: 173 | FF1: 175 | FG1: 176 | FH1: 177 | FI1: 179 | FJ1: 180 | FK1: 181 | FL1: 182 | FM1: 183 | FN1: 185 | FO1: 186 | FP1: 187 | FQ1: 188 | FR1: 189 | FS1: 191 | FT1: 192 | FU1: 193 | FV1: 194 | FW1: 195 | FX1: 196 | FY1: 197 | FZ1: 198 | GA1: 199 | GB1: 200 | GC1: 201 | GD1: 202 | GE1: 203 | GF1: 204 | GG1: 205 | GH1: 206 | GI1: 207 | GJ1: 208 | GK1: 209 | GL1: 210 | GM1: 211 | GN1: 211 | GO1: 212 | GP1: 213 | GQ1: 214 | GR1: 215 | GS1: 216 | GT1: 216 | GU1: 217 | GV1: 218 | GW1: 219 | GX1: 219 | GY1: 220 | GZ1: 221 | HA1: 221 | HB1: 222 | HC1: 223 | HD1: 223 | HE1: 224 | HF1: 225 | HG1: 225 | HH1: 226 | HI1: 227 | HJ1: 227 | HK1: 228 | HL1: 228 | HM1: 229 | HN1: 229 | HO1: 230 | HP1: 231 | HQ1: 231 | HR1: 232 | HS1: 232 | HT1: 233 | HU1: 233 | HV1: 234 | HW1: 234 | HX1: 234 | HY1: 235 | HZ1: 235 | IA1: 236 | IB1: 236 | IC1: 237 | ID1: 237 | IE1: 237 | IF1: 238 | IG1: 238 | IH1: 239 | II1: 239 | IJ1: 239 | IK1: 240 | IL1: 240 | IM1: 240 | IN1: 241 | IO1: 241 | IP1: 241 | IQ1: 242 | IR1: 242 | IS1: 242 | IT1: 243 | IU1: 243 | IV1: 243
